Workbook

Sheet Janeiro 
A1: Nota Fiscal | B1: Emissão | C1: Destinatário | D1: Descrição | E1: Valor Venda | F1: Mão de Obra | G1: Vencimento | H1: Data pagto | I1: OBS | J1: Em aberto Valor | L1: Soares | N1: Componarte
A2: 16412 | B2: 08.01.25 | C2: Soares | D2: Croco metal | F2: 365.03 | G2: 05.02.25 | H2: 45691 | L2: =F73 -> 28250.66
A3: 16437 | B3: 10.01.25 | C3: Soares | D3: Croco | F3: 137.17 | G3: 06.02.25 | H3: 45691
F4: 136 | G4: 13.02.25 | H4: 45698
F5: 136 | G5: 20.02.25 | H5: 45708
A6: 16488 | B6: 14.01.25 | C6: Soares | F6: 89.65 | G6: 11.02.25 | H6: 45698
F7: 88 | G7: 18.02.25 | H7: 45706
F8: 88 | G8: 25.02.25 | H8: 45713
A9: 16540 | B9: 17.01.25 | C9: Soares | D9: Crocodile | F9: 135.24 | G9: 14.02.25 | H9: 45698
A10: 16542 | B10: 17.01.25 | C10: Soares | D10: Rafia glow | F10: 267.38 | G10: 14.02.25 | H10: 45698
A11: 16541 | B11: 17.01.25 | C11: Soares | D11: Rafia glow | F11: 423.78 | G11: 14.02.25 | H11: 45698
F12: 423.78 | G12: 21.02.25 | H12: 45698
F13: 423.78 | G13: 28.02.25 | H13: 45698
A14: 16545 | B14: 20.01.25 | C14: Soares | D14: Croco | F14: 1093.78 | G14: 17.02.25 | H14: 45706
F15: 1091 | G15: 24.02.25 | H15: 45712
F16: 1091 | G16: 03.03.25 | H16: 45721
A17: 16575 | B17: 21.01.25 | C17: Soares | D17: Croco | F17: 319.93 | G17: 18.02.25 | H17: 45706
F18: 317 | G18: 25.02.25 | H18: 45713
F19: 317 | G19: 04.03.25 | H19: 45721
A20: 16600 | B20: 22.01.25 | C20: Soares | D20: Rafia | F20: 361.31 | G20: 19.02.25 | H20: 45706
F21: 361 | G21: 26.02.25 | H21: 45714
F22: 361 | G22: 05.03.25 | H22: 45721
A23: 16615 | B23: 23.01.25 | C23: Soares | D23: Croco | F23: 138 | G23: 20.02.25 | H23: 45708
A24: 16616 | B24: 23.01.25 | C24: Soares | D24: Croco | F24: 374.96 | G24: 20.02.25 | H24: 45708
F25: 373 | G25: 27.02.25 | H25: 45715
F26: 373 | G26: 06.03.25 | H26: 45722
A27: 16618 | B27: 23.01.25 | C27: Soares | D27: Lezard Metalic | F27: 472.5 | G27: 20.02.25 | H27: 45708
F28: 470 | G28: 27.02.25 | H28: 45715
F29: 470 | G29: 06.03.25 | H29: 45722
A30: 16619 | B30: 23.01.25 | C30: Soares | D30: Lezard Metalic | F30: 468.13 | G30: 20.02.25 | H30: 45708
F31: 468 | G31: 27.02.25 | H31: 45715
F32: 468 | G32: 06.03.25 | H32: 45722
A33: DL | B33: 24.01.25 | C33: DL | D33: Materiais diversos | E33: 2637 | G33: 20.02.25 | J33: =E33 -> 2637 | K33: Venda Neomir
E34: 3800 | G34: 01.03.25 | J34: =E34 -> 3800 | K34: Venda Neomir
E35: 3800 | G35: 08.03.25 | J35: =E35 -> 3800 | K35: Venda Neomir
E36: 3800 | G36: 20.03.25 | J36: =E36 -> 3800 | K36: Venda Neomir
E37: 3800 | G37: 22.03.25 | J37: =E37 -> 3800 | K37: Venda Neomir
E38: 3800 | G38: 29.03.29 | J38: =E38 -> 3800 | K38: Venda Neomir
A39: 16639 | B39: 24.01.25 | C39: Soares | D39: Croco Metal | F39: 421.74 | G39: 21.02.25 | H39: 45708
F40: 421.74 | G40: 28.02.25 | H40: 45716
...

Sheet Fevereiro 
A1: Nota Fiscal | B1: Emissão | C1: Destinatário | D1: Descrição | E1: Valor Venda | F1: Mão de Obra | G1: Vencimento | H1: Data pagto | I1: OBS | J1: Em aberto Valor | L1: Soares | N1: Componarte
A2: 16787 | B2: 05.02.25 | C2: Soares | D2: Rafia Glow | F2: 1075.77 | G2: 05.03.25 | H2: 45722
F3: 1075 | G3: 12.03.25 | H3: 45728
F4: 1075 | G4: 19.03.25 | H4: 45735
A5: 16796 | B5: 05.02.25 | C5: Soares | D5: Croco | F5: 1033.36 | G5: 05.03.25 | H5: 45721
F6: 1031 | G6: 12.03.25 | H6: 45728
F7: 1031 | G7: 19.03.25 | H7: 45735
A8: 16826 | B8: 07.02.25 | C8: Soares | D8: Croco Metal | F8: 362.71 | G8: 07.03.25 | H8: 45723
A9: 16827 | B9: 07.02.25 | C9: Soares | D9: Croco Metal | F9: 184.61 | G9: 07.03.25 | H9: 45723
A10: 16870 | B10: 11.02.25 | C10: Soares | D10: Rafia | F10: 411.24 | G10: 11.03.24 | H10: 45727
F11: 409 | G11: 18.03.25 | H11: 45734
F12: 409 | G12: 25.03.25 | H12: 45741
A13: 16876 | B13: 11.02.25 | C13: Soares | D13: Rafia Glow | F13: 984.1 | G13: 11.03.24 | H13: 45727
F14: 983 | G14: 18.03.25 | H14: 45734
F15: 983 | G15: 25.03.25 | H15: 45741
A16: 16916 | B16: 13.02.25 | C16: Soares | D16: Croco | F16: 138 | G16: 13.03.25 | H16: 45729
A17: 16917 | B17: 13.02.25 | C17: Soares | D17: Crocodile | F17: 134.55 | G17: 13.03.25 | H17: 45729
A18: 16943 | B18: 14.02.25 | C18: Soares | D18: Rafia Glow/ Napa | F18: 583.43 | G18: 14.03.25 | H18: 45730
F19: 582 | G19: 21.03.25 | H19: 45735
F20: 582 | G20: 28.03.25 | H20: 45744
A21: 16969 | B21: 18.02.24 | C21: Soares | D21: Croco | F21: 410.38 | G21: 18.03.25 | H21: 45734
F22: 409 | G22: 25.03.25 | H22: 45741
A23: 17140 | B23: 28.02.25 | C23: Soares | D23: Rafia Napa New | F23: 542.68 | G23: 28.03.25 | H23: 45744
F24: 542 | G24: 04.04.25 | H24: 45751
F25: 542 | G25: 11.04.25 | H25: 45758
A27: Total Faturado Mão de Obra | E27: =SUM(E2:E26) -> 0 | F27: =SUM(F2:F26) -> 15513.83
A28: Total Faturado Venda
D29: =(F27+E28) -> 15513.83
A32: Mês | B32: Frete 2021 | C32: Frete 2022 | D32: Frete 2023 | E32: Frete 2024 | F32: Frete 2025
A33: Janeiro | B33: 19219.28 | C33: 109492.58 | D33: 126073.37 | E33: 270562.53 | F33: ='Janeiro '!F79 -> 49887.66
A34: Fevereiro | B34: 18377.75 | C34: 151228.71 | D34: 166235.96 | E34: 324984.97 | F34: =D29 -> 15513.83
A35: Março | B35: 25009.87 | C35: 119148.49 | D35: 119814.85 | E35: 256001.57
A36: Abril | B36: 34211.96 | C36: 238129.97 | D36: 112668.22 | E36: 136419.94
A37: Maio | B37: 130599.69 | C37: 150026.72 | D37: 39597.94 | E37: 57014.4
A38: Junho | B38: 97973.1 | C38: 208724.8 | D38: 77419.24 | E38: 259261.92
A39: Julho | B39: 309004.57 | C39: 130036.72 | D39: 74963.62 | E39: 191964.91
A40: Agosto | B40: 436765.8 | C40: 211762.02 | D40: 152485.66 | E40: 273158.85
A41: Setembro | B41: 355927.94 | C41: 534003.5 | D41: 171282.48 | E41: 63159.51
A42: Outubro | B42: 540038.64 | C42: 96571.01 | D42: 168433.06 | E42: 53077.38
A43: Novembro | B43: 248566.76 | C43: 33008.07 | D43: 155757.68 | E43: 15517.44
...

Sheet Março
A1: Nota Fiscal | B1: Emissão | C1: Destinatário | D1: Descrição | E1: Valor Venda | F1: Mão de Obra | G1: Vencimento | H1: Data pagto | I1: OBS | J1: Em aberto Valor | L1: Soares | N1: Componarte
A2: 17162 | B2: 03.02.25 | C2: Soares | D2: Rafia Glow | F2: 2359.99 | G2: 28.03.25 | H2: 45747
F3: 2358 | G3: 04.04.25 | H3: 45757
F4: 2358 | G4: 11.04.25 | H4: 45761
A5: 17174 | B5: 04.03.25 | C5: Soares | D5: Rafia Napa | F5: 361.31 | G5: 01.04.25 | H5: 45748
F6: 361 | G6: 08.04.25 | H6: 45757
F7: 361 | G7: 15.04.25 | H7: 45762
A8: 17212 | B8: 07.03.25 | C8: Soares | D8: Baby Croco | F8: 689.53 | G8: 04.04.25 | H8: 45751
F9: 688 | G9: 11.04.25 | H9: 45758
F10: 688 | G10: 18.04.25 | H10: 45764
F11: 0
F12: 0
A13: 17213 | B13: 07.03.25 | C13: Soares | D13: Baby Croco | F13: 730.69 | G13: 04.04.25 | H13: 45751
F14: 729 | G14: 11.04.25 | H14: 45758
F15: 729 | G15: 18.04.25 | H15: 45764
A16: 17283 | B16: 13.03.25 | C16: Soares | D16: Rafia Napa Natural | F16: 1003.38 | G16: 10.04.25 | H16: 45757
F17: 1002 | G17: 17.04.25 | H17: 45764
F18: 1002 | G18: 24.04.25 | H18: 45771
A19: 17290 | B19: 13.03.25 | C19: Sores | D19: Croco Branco | F19: 1071.97 | G19: 10.04.25 | H19: 45757
F20: 1070 | G20: 17.04.25 | H20: 45764
F21: 1070 | G21: 24.04.25 | H21: 45771
A22: 17312 | B22: 14.03.25 | C22: Soares | D22: Croco Metal | F22: 183.68 | G22: 11.04.25 | H22: 45758
A23: 17313 | B23: 14.03.25 | C23: Soares | D23: Croco Metal | F23: 406.95 | G23: 11.04.25 | H23: 45758
F24: 405 | G24: 18.04.25 | H24: 45764
A25: 17344 | B25: 19.03.25 | C25: Soares | D25: Rafia Napa | F25: 362.76 | G25: 16.04.25 | H25: 45762
F26: 362 | G26: 23.04.25 | H26: 45770
F27: 362 | G27: 30.04.25 | H27: 45777
A28: 17364 | B28: 20.03.25 | C28: Soares | D28: Croco | F28: 363.98 | G28: 17.04.25 | H28: 45764
A29: 17365 | B29: 20.03.25 | C29: Soares | D29: Croco | F29: 265.65 | G29: 17.04.25 | H29: 45764
A30: 17366 | B30: 20.03.25 | C30: Soares | D30: Baby Croco | F30: 369.73 | G30: 17.04.25 | H30: 45764
F31: 368 | G31: 24.04.25 | H31: 45771
F32: 368 | G32: 01.05.25 | H32: 45777
A33: 17401 | B33: 24.03.25 | C33: Soares | D33: Iguana Preto | F33: 401.13 | G33: 21.04.25 | H33: 45769
F34: 401 | G34: 28.04.25 | H34: 45777
A35: 17418 | B35: 25.03.25 | C35: Soares | D35: Iguana Rocha | F35: 101.78 | G35: 22.04.25 | H35: 45769
A36: 17423 | B36: 26.03.25 | C36: Soares | D36: Croco/Rafia | F36: 1585.88 | G36: 23.04.25 | H36: 45770
F37: 1585 | G37: 30.04.25 | H37: 45777
F38: 1585 | G38: 07.05.25 | H38: 45783
A39: 17421 | B39: 26.03.25 | C39: Soares | D39: Reptil | F39: 136.28 | G39: 23.04.25 | H39: 45770
A40: 17453 | B40: 27.03.25 | C40: Soares | D40: Rafia/Croco | F40: 1171.86 | G40: 24.04.25 | H40: 45771
...

Sheet Abril
A1: Nota Fiscal | B1: Emissão | C1: Destinatário | D1: Descrição | E1: Valor Venda | F1: Mão de Obra | G1: Vencimento | H1: Data pagto | I1: OBS | J1: Em aberto Valor
A2: 17575 | B2: 08.04.25 | C2: Soares | D2: Baby Croco | F2: 485.1 | G2: 06.05.25 | H2: 45783
F3: 483 | G3: 13.05.25 | H3: 45791
F4: 483 | G4: 20.05.25 | H4: 45797
A5: 17589 | B5: 08.04.25 | C5: Soares | D5: Croco metal/Rafia | F5: 1245.87 | G5: 06.05.25 | H5: 45783
F6: 1244 | G6: 13.05.25 | H6: 45791
F7: 1244 | G7: 20.05.25 | H7: 45797
A8: 17590 | B8: 08.04.25 | C8: Soares | D8: Rafia Napa | F8: 1185.23 | G8: 06.05.25 | H8: 45783
F9: 1185 | G9: 13.05.25 | H9: 45791
F10: 1185 | G10: 20.05.25 | H10: 45797
A11: 17591 | B11: 08.04.25 | C11: Soares | D11: Croco | F11: 368.28 | G11: 06.05.25 | H11: 45783
F12: 367 | G12: 13.05.25 | H12: 45791
F13: 367 | G13: 20.05.25 | H13: 45797
A14: 17620 | B14: 11.04.25 | C14: Soares | D14: Rafia Napa/Glow | F14: 1082.74 | G14: 09.05.25 | H14: 45786
F15: 1081 | G15: 16.05.25 | H15: 45791
F16: 1081 | G16: 23.05.25 | H16: 45798
A17: 17621 | B17: 11.04.25 | C17: Soares | D17: Croco | F17: 267.04 | G17: 09.05.25 | H17: 45786
A18: 17640 | B18: 14.04.25 | C18: Soares | D18: Croco | F18: 362.7 | G18: 12.05.25 | H18: 45791
A19: 17669 | B19: 15.04.25 | C19: Soares | D19: Reptil | F19: 274.28 | G19: 13.05.25 | H19: 45791
A20: 17750 | B20: 22.04.25 | C20: Soares | D20: Croco | F20: 1156.28 | G20: 20.05.25 | H20: 45797
F21: 1156 | G21: 27.05.25 | H21: 45804
F22: 1156 | G22: 03.06.25 | H22: 45811
A23: 17832 | B23: 29.04.25 | C23: Soares | D23: Croco | F23: 1886.01 | G23: 27.05.25 | H23: 45804
F24: 1886 | G24: 03.06.25 | H24: 45812
F25: 1886 | G25: 10.06.25 | H25: 45818
J26: =SUM(J2:J25) -> 0
A27: Total Faturado Mão de Obra | E27: =SUM(E2:E26) -> 0 | F27: =SUM(F2:F26) -> 23117.53
A28: Total Faturado Venda
D29: 0
A32: Mês | B32: Frete 2021 | C32: Frete 2022 | D32: Frete 2023 | E32: Frete 2024 | F32: Frete 2025
A33: Janeiro | B33: 19219.28 | C33: 109492.58 | D33: 126073.37 | E33: 270562.53 | F33: ='Janeiro '!F79 -> 49887.66
A34: Fevereiro | B34: 18377.75 | C34: 151228.71 | D34: 166235.96 | E34: 324984.97 | F34: 15513.83
A35: Março | B35: 25009.87 | C35: 119148.49 | D35: 119814.85 | E35: 256001.57 | F35: 32410.22
A36: Abril | B36: 34211.96 | C36: 238129.97 | D36: 112668.22 | E36: 136419.94 | F36: =SUM(F27) -> 23117.53
A37: Maio | B37: 130599.69 | C37: 150026.72 | D37: 39597.94 | E37: 57014.4
A38: Junho | B38: 97973.1 | C38: 208724.8 | D38: 77419.24 | E38: 259261.92
A39: Julho | B39: 309004.57 | C39: 130036.72 | D39: 74963.62 | E39: 191964.91
A40: Agosto | B40: 436765.8 | C40: 211762.02 | D40: 152485.66 | E40: 273158.85
A41: Setembro | B41: 355927.94 | C41: 534003.5 | D41: 171282.48 | E41: 63159.51
A42: Outubro | B42: 540038.64 | C42: 96571.01 | D42: 168433.06 | E42: 53077.38
...

Sheet Maio 2025
A1: Nota Fiscal | B1: Emissão | C1: Destinatário | D1: Descrição | E1: Valor Venda | F1: Mão de Obra | G1: Vencimento | H1: Data pagto | I1: OBS | J1: Em aberto Valor
A2: 17866 | B2: 05.05.2025 | C2: Soares | F2: 774.41 | G2: 02.06.2025 | H2: 45810 | J2: 0
F3: 772 | G3: 09.06.2025 | H3: 45817 | J3: 0
F4: 772 | G4: 16.06.2025 | H4: 45824 | J4: 0
A5: 17876 | B5: 05.05.25 | C5: Soares | F5: 339.83 | G5: 02.06.2025 | H5: 45810 | J5: 0
F6: 339.82 | G6: 09.06.2025 | H6: 45817 | J6: 0
A7: 17878 | B7: 05.05.25 | C7: Soares | F7: 725.78 | G7: 02.06.2025 | H7: 45810 | J7: 0
F8: 723 | G8: 09.06.2025 | H8: 45817 | J8: 0
F9: 723 | G9: 16.06.2025 | H9: 45824 | J9: 0
A10: 17894 | B10: 06.05.25 | C10: Soares | F10: 342.83 | G10: 03.06.2025 | H10: 45811 | J10: 0
F11: 342 | G11: 10.06.2025 | H11: 45818 | J11: 0
A12: 17893 | B12: 06.05.25 | C12: Soares | F12: 369.68 | G12: 03.06.2025 | H12: 45811 | J12: 0
A13: 17892 | B13: 06.05.25 | C13: Soares | F13: 260.48 | G13: 03.06.2025 | H13: 45810 | J13: 0
A14: 17897 | B14: 06.05.25 | C14: Soares | F14: 426.76 | G14: 03.06.2025 | H14: 45811 | J14: 0
F15: 426 | G15: 10.06.2025 | H15: 45818 | J15: 0
F16: 426 | G16: 17.06.2025 | H16: 45824 | J16: 0
A17: 17921 | B17: 07.05.25 | C17: Soares | F17: 362.75 | G17: 04.06.2025 | H17: 45812 | J17: 0
F18: 362 | G18: 11.06.2025 | H18: 45818 | J18: 0
F19: 362 | G19: 18.06.2025 | H19: 45824 | J19: 0
A20: 18124 | B20: 26.05.25 | C20: Soares | F20: 725.23 | G20: 23.06.2025 | H20: 45831 | J20: 0
F21: 725 | G21: 30.06.2025 | H21: 45838 | J21: 0
F22: 725 | G22: 07.07.2025 | H22: 45845 | J22: 0
A23: 18136 | B23: 27.05.25 | C23: Soares | F23: 405.3 | G23: 24.06.2025 | H23: 45831 | J23: 0
F24: 404 | G24: 01.07.2025 | H24: 45838 | J24: 0
A25: 18193 | B25: 30.05.25 | C25: Soares | F25: 342.83 | G25: 27.06.25 | H25: 45831 | J25: 0
F26: 342 | G26: 04.07.25 | H26: 45838 | J26: 0
F27: 0 | J27: 0
J28: =SUM(J2:J27) -> 0
A29: Total Faturado Mão de Obra | E29: =SUM(E2:E28) -> 0 | F29: =SUM(F2:F27) -> 12519.7
A30: Total Faturado Venda
D31: 0
A34: Mês | B34: Frete 2021 | C34: Frete 2022 | D34: Frete 2023 | E34: Frete 2024 | F34: Frete 2025
A35: Janeiro | B35: 19219.28 | C35: 109492.58 | D35: 126073.37 | E35: 270562.53 | F35: ='Janeiro '!F79 -> 49887.66
A36: Fevereiro | B36: 18377.75 | C36: 151228.71 | D36: 166235.96 | E36: 324984.97 | F36: 15513.83
A37: Março | B37: 25009.87 | C37: 119148.49 | D37: 119814.85 | E37: 256001.57 | F37: 32410.22
A38: Abril | B38: 34211.96 | C38: 238129.97 | D38: 112668.22 | E38: 136419.94 | F38: 23117.53
A39: Maio | B39: 130599.69 | C39: 150026.72 | D39: 39597.94 | E39: 57014.4 | F39: =SUM(F29) -> 12519.7
A40: Junho | B40: 97973.1 | C40: 208724.8 | D40: 77419.24 | E40: 259261.92
A41: Julho | B41: 309004.57 | C41: 130036.72 | D41: 74963.62 | E41: 191964.91
A42: Agosto | B42: 436765.8 | C42: 211762.02 | D42: 152485.66 | E42: 273158.85
...

Sheet Junho 2025
A1: Nota Fiscal | B1: Emissão | C1: Destinatário | D1: Descrição | E1: Valor Venda | F1: Mão de Obra | G1: Vencimento | H1: Data pagto | I1: OBS | J1: Em aberto Valor
A2: 18197 | B2: 02.06.2025 | C2: Soares | F2: 455.03 | G2: 30.06.2025 | H2: 45838 | J2: 0
F3: 453 | G3: 07.07.2025 | H3: 45845 | J3: 0
F4: 453 | G4: 14.07.2025 | H4: 45853 | J4: 0
A5: 18205 | B5: 02.06.2025 | C5: Soares | F5: 272.55 | G5: 30.06.2025 | H5: 45838 | J5: 0
A6: 18219 | B6: 03.06.2025 | C6: Soares | F6: 315.31 | G6: 01.07.2025 | H6: 45838 | J6: 0
F7: 315 | G7: 08.07.2025 | H7: 45845 | J7: 0
F8: 315 | G8: 15.07.2025 | H8: 45853 | J8: 0
A9: 18240 | B9: 04.06.2025 | C9: Soares | F9: 1442.24 | G9: 02.07.2025 | H9: 45838 | J9: 0
F10: 1442 | G10: 09.07.2025 | H10: 45847 | J10: 0
F11: 1442 | G11: 16.07.2025 | H11: 45854 | J11: 0
A12: 18289 | B12: 05.06.2025 | C12: Soares | F12: 671.08 | G12: 03.07.2025 | H12: 45838 | J12: 0
F13: 671 | G13: 10.07.2025 | H13: 45847 | J13: 0
F14: 671 | G14: 17.07.2025 | H14: 45855 | J14: 0
A15: 18340 | B15: 10.06.2025 | C15: Soares | F15: 453.85 | G15: 08.07.2025 | H15: 45845 | J15: 0
F16: 451 | G16: 15.07.2025 | H16: 45853 | J16: 0
F17: 451 | G17: 22.07.2025 | H17: 45860 | J17: 0
A18: 18341 | B18: 10.06.2025 | C18: Soares | F18: 131.1 | G18: 08.07.2025 | H18: 45845 | J18: 0
A19: 18342 | B19: 10.06.2025 | C19: Soares | F19: 263.93 | G19: 08.07.2025 | H19: 45845 | J19: 0
A20: 18343 | B20: 10.06.2025 | C20: Soares | F20: 1158.86 | G20: 08.07.2025 | H20: 45846 | J20: 0
F21: 1158 | G21: 15.07.2025 | H21: 45853 | J21: 0
F22: 1158 | G22: 22.07.2025 | H22: 45860 | J22: 0
A23: 18348 | B23: 10.06.2025 | C23: Soares | F23: 538.6 | G23: 08.07.2025 | H23: 45845 | J23: 0
F24: 538 | G24: 15.07.2025 | H24: 45853 | J24: 0
F25: 538 | G25: 22.07.2025 | H25: 45860 | J25: 0
A26: 18349 | B26: 10.06.2025 | C26: Soares | F26: 683.1 | G26: 08.07.2025 | H26: 45846 | J26: 0
A27: 18354 | B27: 11.06.2025 | C27: Soares | F27: 1134.27 | G27: 09.07.2025 | H27: 45847 | J27: 0
F28: 1132 | G28: 16.07.2025 | H28: 45854 | J28: 0
F29: 1132 | G29: 23.07.2025 | H29: 45861 | J29: 0
A30: 18356 | B30: 11.06.2025 | C30: Soares | F30: 400.2 | G30: 09.07.2025 | H30: 45847 | J30: 0
A31: 18357 | B31: 11.06.2025 | C31: Soares | F31: 403.65 | G31: 09.07.2025 | H31: 45847 | J31: 0
A32: 18358 | B32: 11.06.2025 | C32: Soares | F32: 134.55 | G32: 09.07.2025 | H32: 45847 | J32: 0
A33: 18371 | B33: 11.06.2025 | C33: Soares | F33: 414 | G33: 09.07.2025 | H33: 45847 | J33: 0
A34: 18475 | B34: 18.06.2025 | C34: Soares | F34: 323.45 | G34: 16.07.2025 | H34: 45854 | J34: 0
F35: 323 | G35: 23.07.2025 | H35: 45861 | J35: 0
F36: 323 | G36: 30.07.2025 | H36: 45868 | J36: 0
A37: 18489 | B37: 20.06.2025 | C37: Soares | F37: 1451.91 | G37: 18.07.2025 | H37: 45855 | J37: 0
F38: 1451 | G38: 25.07.2025 | H38: 45862 | J38: 0
F39: 1451 | G39: 01.08.2025 | H39: 45869 | J39: 0
A40: 18541 | B40: 25.06.2025 | C40: Soares | F40: 412.56 | G40: 23.07.025 | H40: 45861 | J40: 0
...

Sheet Julho 2025
A1: Nota Fiscal | B1: Emissão | C1: Destinatário | D1: Descrição | E1: Valor Venda | F1: Mão de Obra | G1: Vencimento | H1: Data pagto | I1: OBS | J1: Em aberto Valor
A2: 18656 | B2: 03.07.2025 | C2: Soares | F2: 591.85 | G2: 31.07.2025 | H2: 45869 | J2: 0
F3: 589 | G3: 07.08.2025 | H3: 45874 | J3: 0
F4: 589 | G4: 14.08.2025 | H4: 45880 | J4: 0
A5: 18666 | B5: 07.07.2025 | C5: Soares | F5: 429.4 | G5: 04.08.2025 | H5: 45874 | J5: 0
F6: 427 | G6: 11.08.2025 | H6: 45880 | J6: 0
F7: 427 | G7: 18.08.2025 | H7: 45888 | J7: 0
A8: 18720 | B8: 09.07.2025 | C8: Soares | F8: 396.75 | G8: 06.08.2025 | H8: 45874 | J8: 0
A9: 18765 | B9: 11.07.2025 | C9: Soares | F9: 127.65 | G9: 08.08.2025 | H9: 45874 | J9: 0
A10: 18838 | B10: 17.07.2025 | C10: Soares | F10: 343.55 | G10: 14.08.2025 | H10: 45901 | J10: 0
F11: 343 | G11: 21.08.2025 | H11: 45908 | J11: 0
A12: 18944 | B12: 24.07.2025 | C12: Soares | F12: 411.1 | G12: 21.08.2025 | H12: 45888 | J12: 0
F13: 410 | G13: 28.08.2025 | H13: 45898 | J13: 0
A14: 18969 | B14: 25.07.2025 | C14: Soares | F14: 408.83 | G14: 23.09.2025 | H14: 45922 | J14: 0
A15: 19052 | B15: 31.07.2025 | C15: Soares | F15: 864.68 | G15: 28.08.2025 | H15: 45898 | J15: 0
F16: 864 | G16: 04.09.2025 | H16: 45901 | J16: 0
F17: 864 | G17: 11.09.2025 | H17: 45908 | J17: 0
F18: 0 | J18: 0
F19: 0 | J19: 0
A20: Total Faturado Mão de Obra | E20: =SUM(E2:E18) -> 0 | F20: =SUM(F2:F19) -> 8086.81
A21: Total Faturado Venda
D22: 0
A25: Mês | B25: Frete 2021 | C25: Frete 2022 | D25: Frete 2023 | E25: Frete 2024 | F25: Frete 2025
A26: Janeiro | B26: 19219.28 | C26: 109492.58 | D26: 126073.37 | E26: 270562.53 | F26: ='Janeiro '!F79 -> 49887.66
A27: Fevereiro | B27: 18377.75 | C27: 151228.71 | D27: 166235.96 | E27: 324984.97 | F27: 15513.83
A28: Março | B28: 25009.87 | C28: 119148.49 | D28: 119814.85 | E28: 256001.57 | F28: 32410.22
A29: Abril | B29: 34211.96 | C29: 238129.97 | D29: 112668.22 | E29: 136419.94 | F29: 23117.53
A30: Maio | B30: 130599.69 | C30: 150026.72 | D30: 39597.94 | E30: 57014.4 | F30: 11710.4
A31: Junho | B31: 97973.1 | C31: 208724.8 | D31: 77419.24 | E31: 259261.92 | F31: 32986.86
A32: Julho | B32: 309004.57 | C32: 130036.72 | D32: 74963.62 | E32: 191964.91 | F32: =F20 -> 8086.81
A33: Agosto | B33: 436765.8 | C33: 211762.02 | D33: 152485.66 | E33: 273158.85
A34: Setembro | B34: 355927.94 | C34: 534003.5 | D34: 171282.48 | E34: 63159.51
A35: Outubro | B35: 540038.64 | C35: 96571.01 | D35: 168433.06 | E35: 53077.38
A36: Novembro | B36: 248566.76 | C36: 33008.07 | D36: 155757.68 | E36: 15517.44
A37: Dezembro | B37: 0 | C37: 18714.12 | D37: 163379.08 | E37: 9580.01
A38: total | B38: 2215695.4 | C38: 2000846.7 | D38: 1528111.2 | E38: =SUM(E26:E37) -> 1910703.4

Sheet Agosto 2025
B2: FRETES
B4: MÊS | D4: 2021 | F4: 2022 | H4: 2023 | J4: 2024 | L4: 2025
B5: JANEIRO | D5: 19219.28 | F5: 109492.58 | H5: 126073.37 | J5: 270562.53 | L5: 49887.66
B6: FEVEREIRO | D6: 18377.75 | F6: 151228.71 | H6: 166235.96 | J6: 324984.97 | L6: 15513.83
B7: MARÇO | D7: 25009.87 | F7: 119148.49 | H7: 119814.85 | J7: 256001.57 | L7: 32410.22
B8: ABRIL | D8: 34211.96 | F8: 238129.97 | H8: 112668.22 | J8: 136419.94 | L8: 23117.53
B9: MAIO | D9: 130599.69 | F9: 150026.72 | H9: 39597.94 | J9: 57014.4 | L9: 11710.4
B10: JUNHO | D10: 97973.1 | F10: 208724.8 | H10: 77419.24 | J10: 259261.92 | L10: 32986.86
B11: JULHO | D11: 309004.57 | F11: 130036.72 | H11: 74963.62 | J11: 191964.91 | L11: 8086.81
B12: AGOSTO | D12: 436765.8 | F12: 211762.02 | H12: 152485.66 | J12: 273158.85 | L12: =D45 -> 23203.36
B13: SETEMBRO | D13: 355927.94 | F13: 534003.5 | H13: 171282.48 | J13: 63159.51
B14: OUTUBRO | D14: 540038.64 | F14: 96571.01 | H14: 168433.06 | J14: 53077.38
B15: NOVEMBRO | D15: 248566.76 | F15: 33008.07 | H15: 155757.68 | J15: 15517.44
B16: DEZEMBRO | D16: 0 | F16: 18714.12 | H16: 163379.08 | J16: 9580.01
B17: TOTAL | D17: =SUM(D5:D16) -> 2215695.4 | F17: =SUM(F5:F16) -> 2000846.7 | H17: =SUM(H5:H16) -> 1528111.2 | J17: =SUM(J5:J16) -> 1910703.4 | L17: =SUM(L5:L16) -> 196916.67
B19: NOTA FISCAL | C19: PEDIDO | D19: DATA DE EMISSÃO | E19: DESTINATÁRIO | F19: REPRESENTANTE | G19: VENDA | H19: MÃO DE OBRA | I19: VENCIMENTO | J19: DATA DE PAGAMENTO | K19: OBS: | L19: VALOR EM ABERTO | M19: .
B20: 19183 | C20: 1734 | D20: 45880 | E20: SOARES | F20: Marcelo | G20: 0 | H20: 364.21 | I20: 45908 | J20: 45908
E21: SOARES | F21: Marcelo | G21: 0 | H21: 363 | I21: 45915 | J21: 45915
E22: SOARES | F22: Marcelo | G22: 0 | H22: 363 | I22: 45922 | J22: 45922
B23: 19226 | C23: 1734 | D23: 45883 | E23: SOARES | F23: Marcelo | G23: 0 | H23: 1248.98 | I23: 45911 | J23: 45908
E24: SOARES | F24: Marcelo | G24: 0 | H24: 1248 | I24: 45918 | J24: 45915
E25: SOARES | F25: Marcelo | G25: 0 | H25: 1248 | I25: 45925 | J25: 45926
B26: 19272 | C26: 1796 | D26: 45887 | E26: SOARES | F26: Marcelo | G26: 0 | H26: 633.51 | I26: 45915 | J26: 45915
E27: SOARES | F27: Marcelo | G27: 0 | H27: 632 | I27: 45922 | J27: 45922
E28: SOARES | F28: Marcelo | G28: 0 | H28: 632 | I28: 45929 | J28: 45929
B29: 19289 | C29: 1819 | D29: 45888 | E29: LC COMPONENTES | F29: Marcelo | G29: 0 | H29: 3841.53 | J29: 45923
E30: LC COMPONENTES | F30: Marcelo | G30: 0 | H30: 0
E31: LC COMPONENTES | F31: Marcelo | G31: 0 | H31: 0
B32: 19331 | C32: 1847 | D32: 45891 | E32: SOARES | F32: Marcelo | G32: 0 | H32: 1665.88 | I32: 45919 | J32: 45915
E33: SOARES | F33: Marcelo | G33: 0 | H33: 1664 | I33: 45926 | J33: 45926
E34: SOARES | F34: Marcelo | G34: 0 | H34: 1664 | I34: 45933 | J34: 45933
B35: 19353 | C35: 1849 | D35: 45894 | E35: SOARES | F35: Marcelo | G35: 0 | H35: 578.93 | I35: 45922 | J35: 45951
E36: SOARES | F36: Marcelo | G36: 0 | H36: 0
E37: SOARES | F37: Marcelo | G37: 0 | H37: 0
B38: 19441 | C38: 1934 | D38: 45897 | E38: GRIFFE SHOES | F38: Vânia | G38: 1496.1 | H38: 0 | I38: 45897 | J38: 45897
B39: 19463 | C39: 1936 | D39: 45898 | E39: GRIFFE SHOES | F39: Vânia | G39: 1227 | H39: 0 | I39: 45898 | J39: 45898
B40: 19462 | C40: 1922 | D40: 45898 | E40: SOARES | F40: Marcelo | G40: 0 | H40: 1445.22 | I40: 45926 | J40: 45926
E41: SOARES | F41: Marcelo | G41: 0 | H41: 1444 | I41: 45933 | J41: 45929
E42: SOARES | F42: Marcelo | G42: 0 | H42: 1444 | I42: 45940 | J42: 45939
B43: TOTAL VENDA | G43: =SUM(G20:G42) -> 2723.1
...

Sheet Setembro 2025
B2: FRETES
B4: MÊS | D4: 2021 | F4: 2022 | H4: 2023 | J4: 2024 | L4: 2025
B5: JANEIRO | D5: 19219.28 | F5: 109492.58 | H5: 126073.37 | J5: 270562.53 | L5: 49887.66
B6: FEVEREIRO | D6: 18377.75 | F6: 151228.71 | H6: 166235.96 | J6: 324984.97 | L6: 15513.83
B7: MARÇO | D7: 25009.87 | F7: 119148.49 | H7: 119814.85 | J7: 256001.57 | L7: 32410.22
B8: ABRIL | D8: 34211.96 | F8: 238129.97 | H8: 112668.22 | J8: 136419.94 | L8: 23117.53
B9: MAIO | D9: 130599.69 | F9: 150026.72 | H9: 39597.94 | J9: 57014.4 | L9: 11710.4
B10: JUNHO | D10: 97973.1 | F10: 208724.8 | H10: 77419.24 | J10: 259261.92 | L10: 32986.86
B11: JULHO | D11: 309004.57 | F11: 130036.72 | H11: 74963.62 | J11: 191964.91 | L11: 8086.81
B12: AGOSTO | D12: 436765.8 | F12: 211762.02 | H12: 152485.66 | J12: 273158.85 | L12: 22122.22
B13: SETEMBRO | D13: 355927.94 | F13: 534003.5 | H13: 171282.48 | J13: 63159.51 | L13: =D46 -> 36466.42
B14: OUTUBRO | D14: 540038.64 | F14: 96571.01 | H14: 168433.06 | J14: 53077.38 | L14: 0
B15: NOVEMBRO | D15: 248566.76 | F15: 33008.07 | H15: 155757.68 | J15: 15517.44 | L15: 0
B16: DEZEMBRO | D16: 0 | F16: 18714.12 | H16: 163379.08 | J16: 9580.01 | L16: 0
B17: TOTAL | D17: =SUM(D5:D16) -> 2215695.4 | F17: =SUM(F5:F16) -> 2000846.7 | H17: =SUM(H5:H16) -> 1528111.2 | J17: =SUM(J5:J16) -> 1910703.4 | L17: =SUM(L5:L16) -> 232301.95
B19: NOTA FISCAL | C19: PEDIDO | D19: DATA DE EMISSÃO | E19: DESTINATÁRIO | F19: REPREENTANTE | G19: VENDA | H19: MÃO DE OBRA | I19: VENCIMENTO | J19: DATA DE PAGAMENTO | K19: OBS: | L19: VALOR EM ABERTO | M19: .
B20: 19488 | C20: 1922 | D20: 45902 | E20: SOARES | F20: MARCELO | G20: 0 | H20: 365.03 | I20: 45930 | J20: 45929
B21: 19547 | C21: 1966/2000 | D21: 45905 | E21: SOARES | F21: MARCELO | G21: 0 | H21: 2571.04 | I21: 45933 | J21: 45933
E22: SOARES | F22: MARCELO | G22: 0 | H22: 2569 | I22: 45940 | J22: 45939
E23: SOARES | F23: MARCELO | G23: 0 | H23: 2569 | I23: 45947 | J23: 45945
B24: 19589 | C24: 2016 | D24: 45910 | E24: SOARES | F24: MARCELO | G24: 0 | H24: 120.75 | I24: 45938 | J24: 45971
B25: 19590 | C25: 2000 | D25: 45910 | E25: SOARES | F25: MARCELO | G25: 0 | H25: 348.75 | I25: 45938 | J25: 45939
E26: SOARES | F26: MARCELO | G26: 0 | H26: 347 | I26: 45945 | J26: 45945
E27: SOARES | F27: MARCELO | G27: 0 | H27: 347 | I27: 45952 | J27: 45951
B28: 19643 | C28: 2066 | D28: 45915 | E28: LC COMPONENTES | F28: MARCELO | G28: 0 | H28: 1400.67 | I28: 45950 | J28: 45950
B29: 19650 | C29: 2092 | D29: 45915 | E29: SOARES | F29: MARCELO | G29: 0 | H29: 407.1 | I29: 45943 | J29: 45945
B30: 19703 | C30: 2092 | D30: 45917 | E30: SOARES | F30: MARCELO | G30: 0 | H30: 917.93 | I30: 45945 | J30: 45945
E31: SOARES | F31: MARCELO | G31: 0 | H31: 915 | I31: 45952 | J31: 45951
E32: SOARES | F32: MARCELO | G32: 0 | H32: 915 | I32: 45959 | J32: 45957
B33: 19747 | C33: 2126 | D33: 45919 | E33: SOARES | F33: MARCELO | G33: 0 | H33: 408.75 | I33: 45947 | J33: 45945
E34: SOARES | F34: MARCELO | G34: 0 | H34: 408 | I34: 45954 | J34: 45951
E35: SOARES | F35: MARCELO | G35: 0 | H35: 408 | I35: 45961 | J35: 45957
B36: 19769 | C36: 2152 | D36: 45922 | E36: LC COMPONENTES | F36: MARCELO | G36: 0 | H36: 1357.29 | I36: 45957 | J36: 45957
B37: 19770 | C37: 2183 | D37: 45922 | E37: SOARES | F37: MARCELO | G37: 0 | H37: 1484.52 | I37: 45950 | J37: 45951
E38: SOARES | F38: MARCELO | G38: 0 | H38: 1483 | I38: 45957 | J38: 45957
E39: SOARES | F39: MARCELO | G39: 0 | H39: 1483 | I39: 45964 | J39: 45965
B40: 19908 | C40: 2280 | D40: 45930 | E40: SOARES | F40: MARCELO | G40: 0 | H40: 913.59 | I40: 45958 | J40: 45957
E41: SOARES | F41: MARCELO | G41: 0 | H41: 912 | I41: 45965 | J41: 45966
E42: SOARES | F42: MARCELO | G42: 0 | H42: 912 | I42: 45972 | J42: 45973
B43: 19705/06 | D43: 45918 | E43: NH TEX | F43: MAT. SEGUNDA | G43: 12903 | H43: 0
...

Sheet Outubro 2025 
B2: FRETES
B4: MÊS | D4: 2021 | F4: 2022 | H4: 2023 | J4: 2024 | L4: 2025
B5: JANEIRO | D5: 19219.28 | F5: 109492.58 | H5: 126073.37 | J5: 270562.53 | L5: 49887.66
B6: FEVEREIRO | D6: 18377.75 | F6: 151228.71 | H6: 166235.96 | J6: 324984.97 | L6: 15513.83
B7: MARÇO | D7: 25009.87 | F7: 119148.49 | H7: 119814.85 | J7: 256001.57 | L7: 32410.22
B8: ABRIL | D8: 34211.96 | F8: 238129.97 | H8: 112668.22 | J8: 136419.94 | L8: 23117.53
B9: MAIO | D9: 130599.69 | F9: 150026.72 | H9: 39597.94 | J9: 57014.4 | L9: 11710.4
B10: JUNHO | D10: 97973.1 | F10: 208724.8 | H10: 77419.24 | J10: 259261.92 | L10: 32986.86
B11: JULHO | D11: 309004.57 | F11: 130036.72 | H11: 74963.62 | J11: 191964.91 | L11: 8086.81
B12: AGOSTO | D12: 436765.8 | F12: 211762.02 | H12: 152485.66 | J12: 273158.85 | L12: 22122.22
B13: SETEMBRO | D13: 355927.94 | F13: 534003.5 | H13: 171282.48 | J13: 63159.51 | L13: 36466.42
B14: OUTUBRO | D14: 540038.64 | F14: 96571.01 | H14: 168433.06 | J14: 53077.38 | L14: =D67 -> 101839.17
B15: NOVEMBRO | D15: 248566.76 | F15: 33008.07 | H15: 155757.68 | J15: 15517.44 | L15: 0
B16: DEZEMBRO | D16: 0 | F16: 18714.12 | H16: 163379.08 | J16: 9580.01 | L16: 0
B17: TOTAL | D17: =SUM(D5:D16) -> 2215695.4 | F17: =SUM(F5:F16) -> 2000846.7 | H17: =SUM(H5:H16) -> 1528111.2 | J17: =SUM(J5:J16) -> 1910703.4 | L17: =SUM(L5:L16) -> 334141.12
B19: NOTA FISCAL | C19: PEDIDO | D19: DATA DE EMISSÃO | E19: DESTINATÁRIO | F19: REPRESENTANTE | G19: VENDA | H19: MÃO DE OBRA | I19: VENCIMENTO | J19: DATA DE PAGAMENTO | K19: OBS: | L19: VALOR EM ABERTO | M19: VALOR PAGO
B20: 19970 | C20: 2280 | D20: 45933 | E20: SOARES | F20: MARCELO | G20: 0 | H20: 400.89 | I20: 45961 | J20: 45957 | L20: =Tabela224[[#This Row],[VENDA]]+Tabela224[[#This Row],[MÃO DE OBRA]]-M20 -> 400.89
E21: SOARES | F21: MARCELO | G21: 0 | H21: 399 | I21: 45968 | J21: 45966 | L21: =Tabela224[[#This Row],[VENDA]]+Tabela224[[#This Row],[MÃO DE OBRA]]-M21 -> 399
E22: SOARES | F22: MARCELO | G22: 0 | H22: 399 | I22: 45975 | J22: 45973 | L22: =Tabela224[[#This Row],[VENDA]]+Tabela224[[#This Row],[MÃO DE OBRA]]-M22 -> 399
B23: 19997 | C23: 2404 | D23: 45935 | E23: RM | F23: MARCIANO | G23: 1554 | H23: 0 | I23: 45939 | J23: 45939 | L23: =Tabela224[[#This Row],[VENDA]]+Tabela224[[#This Row],[MÃO DE OBRA]]-M23 -> 1554
B24: 19999 | C24: 2349 | D24: 45936 | E24: SOARES | F24: MARCELO | G24: 0 | H24: 2241.37 | I24: 45964 | J24: 45965 | L24: =Tabela224[[#This Row],[VENDA]]+Tabela224[[#This Row],[MÃO DE OBRA]]-M24 -> 2241.37
E25: SOARES | F25: MARCELO | G25: 0 | H25: 2241 | I25: 45971 | J25: 45971 | L25: =Tabela224[[#This Row],[VENDA]]+Tabela224[[#This Row],[MÃO DE OBRA]]-M25 -> 2241
E26: SOARES | F26: MARCELO | G26: 0 | H26: 2241 | I26: 45978 | J26: 45978 | L26: =Tabela224[[#This Row],[VENDA]]+Tabela224[[#This Row],[MÃO DE OBRA]]-M26 -> -0.11 | M26: 2241.11
B27: 20001 | C27: 2349 | D27: 45936 | E27: SOARES | F27: MARCELO | G27: 0 | H27: 576.73 | I27: 45964 | J27: 45965 | L27: =Tabela224[[#This Row],[VENDA]]+Tabela224[[#This Row],[MÃO DE OBRA]]-M27 -> 576.73
E28: SOARES | F28: MARCELO | G28: 0 | H28: 576 | I28: 45971 | J28: 45971 | L28: =Tabela224[[#This Row],[VENDA]]+Tabela224[[#This Row],[MÃO DE OBRA]]-M28 -> 576
E29: SOARES | F29: MARCELO | G29: 0 | H29: 576 | I29: 45978 | J29: 45978 | L29: =Tabela224[[#This Row],[VENDA]]+Tabela224[[#This Row],[MÃO DE OBRA]]-M29 -> -0.24 | M29: 576.24
B30: 20019 | C30: 2349 | D30: 45937 | E30: SOARES | F30: MARCELO | G30: 0 | H30: 487.79 | I30: 45965 | J30: 45966 | L30: =Tabela224[[#This Row],[VENDA]]+Tabela224[[#This Row],[MÃO DE OBRA]]-M30 -> 487.79
E31: SOARES | F31: MARCELO | G31: 0 | H31: 485 | I31: 45972 | J31: 45973 | L31: =Tabela224[[#This Row],[VENDA]]+Tabela224[[#This Row],[MÃO DE OBRA]]-M31 -> 485
E32: SOARES | F32: MARCELO | G32: 0 | H32: 485 | I32: 45979 | J32: 45980 | L32: =Tabela224[[#This Row],[VENDA]]+Tabela224[[#This Row],[MÃO DE OBRA]]-M32 -> -0.92 | M32: 485.92
B33: 20103 | C33: 2412 | D33: 45940 | E33: SOARES | F33: MARCELO | G33: 0 | H33: 404.31 | I33: 45968 | J33: 45966 | L33: =Tabela224[[#This Row],[VENDA]]+Tabela224[[#This Row],[MÃO DE OBRA]]-M33 -> 404.31
E34: SOARES | F34: MARCELO | G34: 0 | H34: 403 | I34: 45975 | J34: 45973 | L34: =Tabela224[[#This Row],[VENDA]]+Tabela224[[#This Row],[MÃO DE OBRA]]-M34 -> 403
B35: 20104 | C35: 2435 | D35: 45940 | E35: SOARES | F35: MARCELO | G35: 0 | H35: 132.83 | I35: 45968 | J35: 45971 | L35: =Tabela224[[#This Row],[VENDA]]+Tabela224[[#This Row],[MÃO DE OBRA]]-M35 -> 132.83
B36: 20105 | C36: 2435 | D36: 45940 | E36: SOARES | F36: MARCELO | G36: 0 | H36: 270.83 | I36: 45968 | J36: 45971 | L36: =Tabela224[[#This Row],[VENDA]]+Tabela224[[#This Row],[MÃO DE OBRA]]-M36 -> 270.83
B37: 20122 | C37: 2428 | D37: 45943 | E37: SOARES | F37: MARCELO | G37: 0 | H37: 369.68 | I37: 45971 | J37: 45973 | L37: =Tabela224[[#This Row],[VENDA]]+Tabela224[[#This Row],[MÃO DE OBRA]]-M37 -> 369.68
B38: 378 | C38: 338 | D38: 45943 | E38: RM | F38: MARCIANO | G38: 518 | H38: 0 | I38: 45940 | J38: 45940 | L38: =Tabela224[[#This Row],[VENDA]]+Tabela224[[#This Row],[MÃO DE OBRA]]-M38 -> 518
B39: 20164 | C39: 2428 | D39: 45945 | E39: SOARES | F39: MARCELO | G39: 0 | H39: 679.23 | I39: 45973 | J39: 45973 | L39: =Tabela224[[#This Row],[VENDA]]+Tabela224[[#This Row],[MÃO DE OBRA]]-M39 -> 679.23
E40: SOARES | F40: MARCELO | G40: 0 | H40: 679 | I40: 45980 | J40: 45980 | L40: =Tabela224[[#This Row],[VENDA]]+Tabela224[[#This Row],[MÃO DE OBRA]]-M40 -> -0.07 | M40: 679.07
E41: SOARES | F41: MARCELO | G41: 0 | H41: 679 | I41: 45987 | J41: 45989 | L41: =Tabela224[[#This Row],[VENDA]]+Tabela224[[#This Row],[MÃO DE OBRA]]-M41 -> -0.08 | M41: 679.08
B42: 388 | C42: 349 | D42: 45946 | E42: VR | F42: CLEMILSON | G42: 1077.6 | H42: 0 | I42: 45945 | J42: 45945 | L42: =Tabela224[[#This Row],[VENDA]]+Tabela224[[#This Row],[MÃO DE OBRA]]-M42 -> 1077.6
B43: 20244 | C43: 2515 | D43: 45950 | E43: SOARES | F43: MARCELO | G43: 0 | H43: 908.07 | I43: 45978 | J43: 45978 | L43: =Tabela224[[#This Row],[VENDA]]+Tabela224[[#This Row],[MÃO DE OBRA]]-M43 -> 0.73 | M43: 907.34
...

Sheet Novembro 2025 
B2: FRETES
B4: MÊS | C4: SMART | H4: STK
C5: 2023 | D5: 2024 | E5: 2025 | F5: 2026 | G5: 2027 | H5: 2025 | I5: 2026 | J5: 2027 | K5: 2028 | L5: 2029 | M5: 2030
B6: JANEIRO | C6: 126073.37 | D6: 270562.53 | E6: 49887.66 | F6: 0 | G6: 0 | H6: 0 | I6: 0 | J6: 0 | K6: 0 | L6: 0 | M6: 0
B7: FEVEREIRO | C7: 166235.96 | D7: 324984.97 | E7: 15513.83 | F7: 0 | G7: 0 | H7: 0 | I7: 0 | J7: 0 | K7: 0 | L7: 0 | M7: 0
B8: MARÇO | C8: 119814.85 | D8: 256001.57 | E8: 32410.22 | F8: 0 | G8: 0 | H8: 0 | I8: 0 | J8: 0 | K8: 0 | L8: 0 | M8: 0
B9: ABRIL | C9: 112668.22 | D9: 136419.94 | E9: 23117.53 | F9: 0 | G9: 0 | H9: 0 | I9: 0 | J9: 0 | K9: 0 | L9: 0 | M9: 0
B10: MAIO | C10: 39597.94 | D10: 57014.4 | E10: 11710.4 | F10: 0 | G10: 0 | H10: 0 | I10: 0 | J10: 0 | K10: 0 | L10: 0 | M10: 0
B11: JUNHO | C11: 77419.24 | D11: 259261.92 | E11: 32986.86 | F11: 0 | G11: 0 | H11: 0 | I11: 0 | J11: 0 | K11: 0 | L11: 0 | M11: 0
B12: JULHO | C12: 74963.62 | D12: 191964.91 | E12: 8086.81 | F12: 0 | G12: 0 | H12: 0 | I12: 0 | J12: 0 | K12: 0 | L12: 0 | M12: 0
B13: AGOSTO | C13: 152485.66 | D13: 273158.85 | E13: 22122.22 | F13: 0 | G13: 0 | H13: 0 | I13: 0 | J13: 0 | K13: 0 | L13: 0 | M13: 0
B14: SETEMBRO | C14: 171282.48 | D14: 63159.51 | E14: 36466.42 | F14: 0 | G14: 0 | H14: 0 | I14: 0 | J14: 0 | K14: 0 | L14: 0 | M14: 0
B15: OUTUBRO | C15: 168433.06 | D15: 53077.38 | E15: 99828 | F15: 0 | G15: 0 | H15: 1595.6 | I15: 0 | J15: 0 | K15: 0 | L15: 0 | M15: 0
B16: NOVEMBRO | C16: 155757.68 | D16: 15517.44 | E16: 0 | F16: 0 | G16: 0 | H16: 0 | I16: 0 | J16: 0 | K16: 0 | L16: 0 | M16: 0
B17: DEZEMBRO | C17: 163379.08 | D17: 9580.01 | E17: 0 | F17: 0 | G17: 0 | H17: 0 | I17: 0 | J17: 0 | K17: 0 | L17: 0 | M17: 0
B18: TOTAL | C18: =SUM(C6:C17) -> 1528111.2 | D18: =SUM(D6:D17) -> 1910703.4 | E18: =SUM(E6:E17) -> 332129.95 | F18: =SUM(F6:F17) -> 0 | G18: 0 | H18: =SUM(H6:H17) -> 1595.6 | I18: 0 | J18: =SUM(J6:J17) -> 0 | K18: 0 | L18: =SUM(L6:L17) -> 0 | M18: 0
B19: TOTAL CONSOLIDADO 2025: | D19: =SUM(H18+E18) -> 333725.55
B20: EMPRESA | C20: NOTA FISCAL | D20: PEDIDO | E20: DATA DE EMISSÃO | F20: DESTINATÁRIO | G20: REPRESENTANTE | H20: VENDA | I20: MÃO DE OBRA | J20: VENCIMENTO | K20: DATA DE PAGAMENTO | L20: VALOR PAGO | M20: VALOR EM ABERTO
B21: STK | C21: 448 | D21: 408 | E21: 45971 | F21: MARIOTA | G21: SILVANO | H21: 3000 | I21: 0 | J21: 45971 | K21: 45967 | L21: 3000 | M21: =Tabela2246[[#This Row],[VENDA]]+Tabela2246[[#This Row],[MÃO DE OBRA]]-Tabela2246[[#This Row],[VALOR PAGO]] -> 0
B22: STK | C22: 458 | D22: 409 | E22: 45974 | F22: GLAUCIA | G22: SILVANO | H22: 4500 | I22: 0 | J22: 45974 | K22: 45973 | L22: 4500 | M22: =Tabela2246[[#This Row],[VENDA]]+Tabela2246[[#This Row],[MÃO DE OBRA]]-Tabela2246[[#This Row],[VALOR PAGO]] -> 0
B23: SMART | C23: 20590 | D23: 2783 | E23: 45971 | F23: SOARES | G23: MARCELO | H23: 0 | I23: 522.59 | J23: 45999 | K23: 46003 | L23: 521.52 | M23: =Tabela2246[[#This Row],[VENDA]]+Tabela2246[[#This Row],[MÃO DE OBRA]]-Tabela2246[[#This Row],[VALOR PAGO]] -> 1.07
F24: SOARES | G24: MARCELO | H24: 0 | I24: 521 | J24: 46006 | K24: 46010 | L24: 521.52 | M24: =Tabela2246[[#This Row],[VENDA]]+Tabela2246[[#This Row],[MÃO DE OBRA]]-Tabela2246[[#This Row],[VALOR PAGO]] -> -0.52
F25: SOARES | G25: MARCELO | H25: 0 | I25: 521 | J25: 46013 | K25: 46017 | L25: 521.52 | M25: =Tabela2246[[#This Row],[VENDA]]+Tabela2246[[#This Row],[MÃO DE OBRA]]-Tabela2246[[#This Row],[VALOR PAGO]] -> -0.52
B26: SMART | C26: 20591 | D26: 2801 | E26: 45971 | F26: SOARES | G26: MARCELO | H26: 0 | I26: 364.48 | J26: 45999 | K26: 46003 | L26: 362.82 | M26: =Tabela2246[[#This Row],[VENDA]]+Tabela2246[[#This Row],[MÃO DE OBRA]]-Tabela2246[[#This Row],[VALOR PAGO]] -> 1.66
F27: SOARES | G27: MARCELO | H27: 0 | I27: 362 | J27: 46006 | K27: 46010 | L27: 362.82 | M27: =Tabela2246[[#This Row],[VENDA]]+Tabela2246[[#This Row],[MÃO DE OBRA]]-Tabela2246[[#This Row],[VALOR PAGO]] -> -0.82
F28: SOARES | G28: MARCELO | H28: 0 | I28: 362 | J28: 46013 | K28: 45997 | L28: 362.83 | M28: =Tabela2246[[#This Row],[VENDA]]+Tabela2246[[#This Row],[MÃO DE OBRA]]-Tabela2246[[#This Row],[VALOR PAGO]] -> -0.83
B29: SMART | C29: 20644 | D29: 2838 | E29: 45974 | F29: SOARES | G29: MARCELO | H29: 0 | I29: 490.26 | J29: 46002 | K29: 46003 | L29: 488.75 | M29: =Tabela2246[[#This Row],[VENDA]]+Tabela2246[[#This Row],[MÃO DE OBRA]]-Tabela2246[[#This Row],[VALOR PAGO]] -> 1.51
F30: SOARES | G30: MARCELO | H30: 0 | I30: 488 | J30: 46009 | K30: 46010 | L30: 488.75 | M30: =Tabela2246[[#This Row],[VENDA]]+Tabela2246[[#This Row],[MÃO DE OBRA]]-Tabela2246[[#This Row],[VALOR PAGO]] -> -0.75
F31: SOARES | G31: MARCELO | H31: 0 | I31: 488 | J31: 46016 | K31: 46017 | L31: 488.74 | M31: =Tabela2246[[#This Row],[VENDA]]+Tabela2246[[#This Row],[MÃO DE OBRA]]-Tabela2246[[#This Row],[VALOR PAGO]] -> -0.74
B32: SMART | C32: 20656 | D32: 2888 | E32: 45974 | F32: LEANDRENSE | G32: MARCIANO | H32: 1036 | I32: 0 | J32: 45988 | K32: 45988 | L32: 1036 | M32: =Tabela2246[[#This Row],[VENDA]]+Tabela2246[[#This Row],[MÃO DE OBRA]]-Tabela2246[[#This Row],[VALOR PAGO]] -> 0
B33: STK | C33: 20671 | D33: 2898 | E33: 45975 | F33: SOARES | G33: DIRETO | H33: =26852.98/3 -> 8950.9933 | I33: 0 | J33: 46003 | K33: 46010 | L33: 8950.99 | M33: =Tabela2246[[#This Row],[VENDA]]+Tabela2246[[#This Row],[MÃO DE OBRA]]-Tabela2246[[#This Row],[VALOR PAGO]] -> 0.0033333333
F34: SOARES | G34: DIRETO | H34: 8950.9933 | I34: 0 | J34: 46010 | K34: 46017 | L34: 8950.99 | M34: =Tabela2246[[#This Row],[VENDA]]+Tabela2246[[#This Row],[MÃO DE OBRA]]-Tabela2246[[#This Row],[VALOR PAGO]] -> 0.0033333333
F35: SOARES | G35: DIRETO | H35: 8950.9933 | I35: 0 | J35: 46017 | K35: 46041 | L35: 8951 | M35: =Tabela2246[[#This Row],[VENDA]]+Tabela2246[[#This Row],[MÃO DE OBRA]]-Tabela2246[[#This Row],[VALOR PAGO]] -> -0.0066666667
B36: STK | C36: 20678 | D36: 2850 | E36: 45975 | F36: SOARES | G36: DIRETO | H36: =68611.8/3 -> 22870.6 | I36: 0 | J36: 46003 | K36: 46010 | L36: 22870.6 | M36: =Tabela2246[[#This Row],[VENDA]]+Tabela2246[[#This Row],[MÃO DE OBRA]]-Tabela2246[[#This Row],[VALOR PAGO]] -> 0
F37: SOARES | G37: DIRETO | H37: 22870.6 | I37: 0 | J37: 46010 | K37: 46017 | L37: 22870.6 | M37: =Tabela2246[[#This Row],[VENDA]]+Tabela2246[[#This Row],[MÃO DE OBRA]]-Tabela2246[[#This Row],[VALOR PAGO]] -> 0
F38: SOARES | G38: DIRETO | H38: 22870.6 | I38: 0 | J38: 46017 | K38: 46035 | L38: 22870.6 | M38: =Tabela2246[[#This Row],[VENDA]]+Tabela2246[[#This Row],[MÃO DE OBRA]]-Tabela2246[[#This Row],[VALOR PAGO]] -> 0
B39: STK | C39: 20679 | D39: 2906 | E39: 45975 | F39: SOARES | G39: DIRETO | H39: 8411.59 | I39: 0 | J39: 46003 | K39: 46010 | L39: 8411.59 | M39: =Tabela2246[[#This Row],[VENDA]]+Tabela2246[[#This Row],[MÃO DE OBRA]]-Tabela2246[[#This Row],[VALOR PAGO]] -> 0
F40: SOARES | G40: DIRETO | H40: 8411.59 | I40: 0 | J40: 46010 | K40: 46017 | L40: 8411.59 | M40: =Tabela2246[[#This Row],[VENDA]]+Tabela2246[[#This Row],[MÃO DE OBRA]]-Tabela2246[[#This Row],[VALOR PAGO]] -> 0
F41: SOARES | G41: DIRETO | H41: 8411.59 | I41: 0 | J41: 46017 | K41: 46041 | L41: 8411.59 | M41: =Tabela2246[[#This Row],[VENDA]]+Tabela2246[[#This Row],[MÃO DE OBRA]]-Tabela2246[[#This Row],[VALOR PAGO]] -> 0
B42: SMART | C42: 20707 | D42: 2880 | E42: 45979 | F42: SOARES | G42: MARCELO | H42: 0 | I42: 332.93 | J42: 46007 | K42: 46010 | L42: 332.92 | M42: =Tabela2246[[#This Row],[VENDA]]+Tabela2246[[#This Row],[MÃO DE OBRA]]-Tabela2246[[#This Row],[VALOR PAGO]] -> 0.01
...

Sheet Dezembro 2025
B2: FRETES
B4: MÊS | C4: SMART | H4: STK
C5: 2023 | D5: 2024 | E5: 2025 | F5: 2026 | G5: 2027 | H5: 2025 | I5: 2026 | J5: 2027 | K5: 2028 | L5: 2029 | M5: 2030
B6: JANEIRO | C6: 126073.37 | D6: 270562.53 | E6: 49887.66 | F6: 0 | G6: 0 | H6: 0 | I6: 0 | J6: 0 | K6: 0 | L6: 0 | M6: 0
B7: FEVEREIRO | C7: 166235.96 | D7: 324984.97 | E7: 15513.83 | F7: 0 | G7: 0 | H7: 0 | I7: 0 | J7: 0 | K7: 0 | L7: 0 | M7: 0
B8: MARÇO | C8: 119814.85 | D8: 256001.57 | E8: 32410.22 | F8: 0 | G8: 0 | H8: 0 | I8: 0 | J8: 0 | K8: 0 | L8: 0 | M8: 0
B9: ABRIL | C9: 112668.22 | D9: 136419.94 | E9: 23117.53 | F9: 0 | G9: 0 | H9: 0 | I9: 0 | J9: 0 | K9: 0 | L9: 0 | M9: 0
B10: MAIO | C10: 39597.94 | D10: 57014.4 | E10: 11710.4 | F10: 0 | G10: 0 | H10: 0 | I10: 0 | J10: 0 | K10: 0 | L10: 0 | M10: 0
B11: JUNHO | C11: 77419.24 | D11: 259261.92 | E11: 32986.86 | F11: 0 | G11: 0 | H11: 0 | I11: 0 | J11: 0 | K11: 0 | L11: 0 | M11: 0
B12: JULHO | C12: 74963.62 | D12: 191964.91 | E12: 8086.81 | F12: 0 | G12: 0 | H12: 0 | I12: 0 | J12: 0 | K12: 0 | L12: 0 | M12: 0
B13: AGOSTO | C13: 152485.66 | D13: 273158.85 | E13: 22122.22 | F13: 0 | G13: 0 | H13: 0 | I13: 0 | J13: 0 | K13: 0 | L13: 0 | M13: 0
B14: SETEMBRO | C14: 171282.48 | D14: 63159.51 | E14: 36466.42 | F14: 0 | G14: 0 | H14: 0 | I14: 0 | J14: 0 | K14: 0 | L14: 0 | M14: 0
B15: OUTUBRO | C15: 168433.06 | D15: 53077.38 | E15: 99828 | F15: 0 | G15: 0 | H15: 1595.6 | I15: 0 | J15: 0 | K15: 0 | L15: 0 | M15: 0
B16: NOVEMBRO | C16: 155757.68 | D16: 15517.44 | E16: =Tabela2246[[#Totals],[VENDA]]+Tabela2246[[#Totals],[MÃO DE OBRA]] -> 381690.36 | F16: 0 | G16: 0 | H16: 0 | I16: 0 | J16: 0 | K16: 0 | L16: 0 | M16: 0
B17: DEZEMBRO | C17: 163379.08 | D17: 9580.01 | E17: =Tabela22465[[#Totals],[VENDA]]+Tabela22465[[#Totals],[MÃO DE OBRA]] -> 148680.26 | F17: 0 | G17: 0 | H17: 0 | I17: 0 | J17: 0 | K17: 0 | L17: 0 | M17: 0
B18: TOTAL | C18: =SUM(C6:C17) -> 1528111.2 | D18: =SUM(D6:D17) -> 1910703.4 | E18: =SUM(E6:E17) -> 862500.57 | F18: =SUM(F6:F17) -> 0 | G18: 0 | H18: =SUM(H6:H17) -> 1595.6 | I18: 0 | J18: =SUM(J6:J17) -> 0 | K18: 0 | L18: =SUM(L6:L17) -> 0 | M18: 0
B19: TOTAL CONSOLIDADO 2025: | D19: =SUM(H18+E18) -> 864096.17
B20: EMPRESA | C20: NOTA FISCAL | D20: PEDIDO | E20: DATA DE EMISSÃO | F20: DESTINATÁRIO | G20: REPRESENTANTE | H20: VENDA | I20: MÃO DE OBRA | J20: VENCIMENTO | K20: DATA DE PAGAMENTO | L20: VALOR PAGO | M20: VALOR EM ABERTO | N20: Coluna1
B21: STK | C21: 507 | D21: 428 | E21: 45992 | F21: GLAUCIA | G21: SILVANO | H21: =901*7.5 -> 6757.5 | I21: 0 | J21: 45992 | K21: 46006 | L21: 6757.5 | M21: =Tabela22465[[#This Row],[VENDA]]+Tabela22465[[#This Row],[MÃO DE OBRA]]-Tabela22465[[#This Row],[VALOR PAGO]] -> 0
B22: STK | C22: 20882 | D22: 2993 | E22: 45993 | F22: GLAUCIA | G22: SILVANO | H22: =160*11.97 -> 1915.2 | I22: 0 | J22: 45993 | K22: 45993 | L22: 1915.2 | M22: =Tabela22465[[#This Row],[VENDA]]+Tabela22465[[#This Row],[MÃO DE OBRA]]-Tabela22465[[#This Row],[VALOR PAGO]] -> 0
B23: STK | C23: 20883 | D23: 3050 | E23: 45993 | F23: GLAUCIA | G23: SILVANO | H23: =520*11.97 -> 6224.4 | I23: 0 | J23: 45993 | K23: 45993 | L23: 6224.4 | M23: =Tabela22465[[#This Row],[VENDA]]+Tabela22465[[#This Row],[MÃO DE OBRA]]-Tabela22465[[#This Row],[VALOR PAGO]] -> 0
B24: STK | C24: 525 | D24: 1019 | E24: 46360 | F24: RM CALÇADOS | G24: MARCIANO | H24: 18956.25 | I24: 0 | J24: 46112 | K24: 46122 | L24: 18956.25 | M24: =Tabela22465[[#This Row],[VENDA]]+Tabela22465[[#This Row],[MÃO DE OBRA]]-Tabela22465[[#This Row],[VALOR PAGO]] -> 0
B25: STK | C25: 525 | D25: 1019 | E25: 46360 | F25: RM CALÇADOS | G25: MARCIANO | H25: 18954 | I25: 0 | J25: 46119 | K25: 46150 | L25: 18954 | M25: =Tabela22465[[#This Row],[VENDA]]+Tabela22465[[#This Row],[MÃO DE OBRA]]-Tabela22465[[#This Row],[VALOR PAGO]] -> 0
B26: STK | C26: 525 | D26: 1019 | E26: 46360 | F26: RM CALÇADOS | G26: MARCIANO | H26: 18954 | I26: 0 | J26: 46126 | K26: 46160 | L26: 18954 | M26: =Tabela22465[[#This Row],[VENDA]]+Tabela22465[[#This Row],[MÃO DE OBRA]]-Tabela22465[[#This Row],[VALOR PAGO]] -> 0
B27: STK | C27: 525 | D27: 1019 | E27: 46360 | F27: RM CALÇADOS | G27: MARCIANO | H27: 18954 | I27: 0 | J27: 46133 | K27: 46176 | L27: 18954 | M27: =Tabela22465[[#This Row],[VENDA]]+Tabela22465[[#This Row],[MÃO DE OBRA]]-Tabela22465[[#This Row],[VALOR PAGO]] -> 0
B28: SMART | C28: 20958 | D28: 3078 | E28: 45996 | F28: LC COMPONENTES | G28: MARCELO | H28: 0 | I28: 1404.23 | J28: 45666 | K28: 46035 | L28: 1404.23 | M28: =Tabela22465[[#This Row],[VENDA]]+Tabela22465[[#This Row],[MÃO DE OBRA]]-Tabela22465[[#This Row],[VALOR PAGO]] -> 0
B29: SMART | C29: 20959 | D29: 3106 | E29: 46361 | F29: LC COMPONENTES | G29: MARCELO | I29: 1411.33 | J29: 46031 | K29: 46035 | L29: 1411.33 | M29: =Tabela22465[[#This Row],[VENDA]]+Tabela22465[[#This Row],[MÃO DE OBRA]]-Tabela22465[[#This Row],[VALOR PAGO]] -> 0
B30: SMART | C30: 21045 | D30: 3192 | E30: 46002 | F30: LC COMPONENTES | G30: MARCELO | H30: 0 | I30: =198*7.11 -> 1407.78 | J30: 45672 | K30: 46037 | L30: 1407.78 | M30: =Tabela22465[[#This Row],[VENDA]]+Tabela22465[[#This Row],[MÃO DE OBRA]]-Tabela22465[[#This Row],[VALOR PAGO]] -> 0
B31: SMART | C31: 20905 | D31: 3042 | E31: 45994 | F31: SOARES | G31: MARCELO | H31: 0 | I31: 458.85 | J31: 46022 | K31: 46043 | L31: 458.85 | M31: =Tabela22465[[#This Row],[VENDA]]+Tabela22465[[#This Row],[MÃO DE OBRA]]-Tabela22465[[#This Row],[VALOR PAGO]] -> 0
H32: 0 | I32: 458.85 | J32: 45664 | K32: 46044 | L32: 458.85 | M32: =Tabela22465[[#This Row],[VENDA]]+Tabela22465[[#This Row],[MÃO DE OBRA]]-Tabela22465[[#This Row],[VALOR PAGO]] -> 0
H33: 0 | I33: 458.95 | J33: 45671 | K33: 46055 | L33: 458.85 | M33: =Tabela22465[[#This Row],[VENDA]]+Tabela22465[[#This Row],[MÃO DE OBRA]]-Tabela22465[[#This Row],[VALOR PAGO]] -> 0.1
B34: SMART | C34: 20910 | D34: 3042 | E34: 45994 | F34: SOARES | G34: MARCELO | H34: 0 | I34: =2998.05/3 -> 999.35 | J34: 46022 | K34: 46043 | L34: 999.34 | M34: =Tabela22465[[#This Row],[VENDA]]+Tabela22465[[#This Row],[MÃO DE OBRA]]-Tabela22465[[#This Row],[VALOR PAGO]] -> 0.01
H35: 0 | I35: =2998.05/3 -> 999.35 | J35: 45664 | K35: 46044 | L35: 999.34 | M35: =Tabela22465[[#This Row],[VENDA]]+Tabela22465[[#This Row],[MÃO DE OBRA]]-Tabela22465[[#This Row],[VALOR PAGO]] -> 0.01
H36: 0 | I36: =2998.05/3 -> 999.35 | J36: 45671 | K36: 46055 | L36: 999.35 | M36: =Tabela22465[[#This Row],[VENDA]]+Tabela22465[[#This Row],[MÃO DE OBRA]]-Tabela22465[[#This Row],[VALOR PAGO]] -> 0
B37: SMART | C37: 20995 | D37: 3115 | E37: 46000 | F37: SOARES | G37: MARCELO | H37: 0 | I37: =3437.93/3 -> 1145.9767 | J37: 45663 | K37: 46044 | L37: 1145.97 | M37: =Tabela22465[[#This Row],[VENDA]]+Tabela22465[[#This Row],[MÃO DE OBRA]]-Tabela22465[[#This Row],[VALOR PAGO]] -> 0.0066666667
H38: 0 | I38: =3437.93/3 -> 1145.9767 | J38: 45670 | K38: 46055 | L38: 1145.97 | M38: =Tabela22465[[#This Row],[VENDA]]+Tabela22465[[#This Row],[MÃO DE OBRA]]-Tabela22465[[#This Row],[VALOR PAGO]] -> 0.0066666667
H39: 0 | I39: =3437.93/3 -> 1145.9767 | J39: 45677 | K39: 02/002/26 | L39: 1145.97 | M39: =Tabela22465[[#This Row],[VENDA]]+Tabela22465[[#This Row],[MÃO DE OBRA]]-Tabela22465[[#This Row],[VALOR PAGO]] -> 0.0066666667
B40: SMART | C40: 21058 | D40: 3165 | E40: 46368 | F40: SOARES | G40: MARCELO | H40: 0 | I40: 1030.4 | J40: 46031 | K40: 46055 | L40: 1030.4 | M40: =Tabela22465[[#This Row],[VENDA]]+Tabela22465[[#This Row],[MÃO DE OBRA]]-Tabela22465[[#This Row],[VALOR PAGO]] -> 0
H41: 0 | I41: 1030.4 | J41: 46038 | K41: 46055 | L41: 1030.39 | M41: =Tabela22465[[#This Row],[VENDA]]+Tabela22465[[#This Row],[MÃO DE OBRA]]-Tabela22465[[#This Row],[VALOR PAGO]] -> 0.01
H42: 0 | I42: 1030.41 | J42: 46045 | K42: 46055 | L42: 1030.4 | M42: =Tabela22465[[#This Row],[VENDA]]+Tabela22465[[#This Row],[MÃO DE OBRA]]-Tabela22465[[#This Row],[VALOR PAGO]] -> 0.01
...

Sheet Janeiro 2026
B2: FRETES
B4: MÊS | C4: SMART | H4: STK
C5: 2023 | D5: 2024 | E5: 2025 | F5: 2026 | G5: 2027 | H5: 2025 | I5: 2026 | J5: 2027 | K5: 2028 | L5: 2029 | M5: 2030
B6: JANEIRO | C6: 126073.37 | D6: 270562.53 | E6: 49887.66 | F6: 0 | G6: 0 | H6: 0 | I6: 0 | J6: 0 | K6: 0 | L6: 0 | M6: 0
B7: FEVEREIRO | C7: 166235.96 | D7: 324984.97 | E7: 15513.83 | F7: 0 | G7: 0 | H7: 0 | I7: 0 | J7: 0 | K7: 0 | L7: 0 | M7: 0
B8: MARÇO | C8: 119814.85 | D8: 256001.57 | E8: 32410.22 | F8: 0 | G8: 0 | H8: 0 | I8: 0 | J8: 0 | K8: 0 | L8: 0 | M8: 0
B9: ABRIL | C9: 112668.22 | D9: 136419.94 | E9: 23117.53 | F9: 0 | G9: 0 | H9: 0 | I9: 0 | J9: 0 | K9: 0 | L9: 0 | M9: 0
B10: MAIO | C10: 39597.94 | D10: 57014.4 | E10: 11710.4 | F10: 0 | G10: 0 | H10: 0 | I10: 0 | J10: 0 | K10: 0 | L10: 0 | M10: 0
B11: JUNHO | C11: 77419.24 | D11: 259261.92 | E11: 32986.86 | F11: 0 | G11: 0 | H11: 0 | I11: 0 | J11: 0 | K11: 0 | L11: 0 | M11: 0
B12: JULHO | C12: 74963.62 | D12: 191964.91 | E12: 8086.81 | F12: 0 | G12: 0 | H12: 0 | I12: 0 | J12: 0 | K12: 0 | L12: 0 | M12: 0
B13: AGOSTO | C13: 152485.66 | D13: 273158.85 | E13: 22122.22 | F13: 0 | G13: 0 | H13: 0 | I13: 0 | J13: 0 | K13: 0 | L13: 0 | M13: 0
B14: SETEMBRO | C14: 171282.48 | D14: 63159.51 | E14: 36466.42 | F14: 0 | G14: 0 | H14: 0 | I14: 0 | J14: 0 | K14: 0 | L14: 0 | M14: 0
B15: OUTUBRO | C15: 168433.06 | D15: 53077.38 | E15: 99828 | F15: 0 | G15: 0 | I15: 0 | J15: 0 | K15: 0 | L15: 0 | M15: 0
B16: NOVEMBRO | C16: 155757.68 | D16: 15517.44 | E16: 0 | F16: 0 | G16: 0 | H16: 0 | I16: 0 | J16: 0 | K16: 0 | L16: 0 | M16: 0
B17: DEZEMBRO | C17: 163379.08 | D17: 9580.01 | E17: 0 | F17: 0 | G17: 0 | H17: 0 | I17: 0 | J17: 0 | K17: 0 | L17: 0 | M17: 0
B18: TOTAL | C18: =SUM(C6:C17) -> 1528111.2 | D18: =SUM(D6:D17) -> 1910703.4 | E18: =SUM(E6:E17) -> 332129.95 | F18: =SUM(F6:F17) -> 0 | G18: 0 | H18: =SUM(H6:H17) -> 0 | I18: 0 | J18: =SUM(J6:J17) -> 0 | K18: 0 | L18: =SUM(L6:L17) -> 0 | M18: 0
B19: TOTAL CONSOLIDADO 2026: | D19: =SUM(I18+F18) -> 0
B20: EMPRESA | C20: NOTA FISCAL | D20: PEDIDO | E20: DATA DE EMISSÃO | F20: DESTINATÁRIO | G20: REPRESENTANTE | H20: VENDA | I20: MÃO DE OBRA | J20: VENCIMENTO | K20: DATA DE PAGAMENTO | L20: VALOR PAGO | M20: VALOR EM ABERTO
B21: STK | C21: 21098 | D21: 3229 | E21: 46030 | F21: GLAUCIA | G21: SILVANO | H21: 3704.72 | J21: 46030 | K21: 46030 | L21: 3704.72 | M21: =Tabela224657[[#This Row],[VENDA]]+Tabela224657[[#This Row],[MÃO DE OBRA]]-Tabela224657[[#This Row],[VALOR PAGO]] -> 0
B22: SMART | C22: 21087 | D22: 3202 | E22: 46029 | F22: SOARES | G22: MARCELO | I22: 960.25 | J22: 46057 | K22: 46055 | L22: 960.24 | M22: =Tabela224657[[#This Row],[VENDA]]+Tabela224657[[#This Row],[MÃO DE OBRA]]-Tabela224657[[#This Row],[VALOR PAGO]] -> 0.01
B23: SMART | C23: 21087 | D23: 3202 | E23: 46029 | F23: SOARES | G23: MARCELO | I23: 960.25 | J23: 46064 | K23: 46055 | L23: 960.25 | M23: =Tabela224657[[#This Row],[VENDA]]+Tabela224657[[#This Row],[MÃO DE OBRA]]-Tabela224657[[#This Row],[VALOR PAGO]] -> 0
B24: SMART | C24: 21087 | D24: 3202 | E24: 46029 | F24: SOARES | G24: MARCELO | I24: 960.25 | J24: 46071 | K24: 46055 | L24: 960.25 | M24: =Tabela224657[[#This Row],[VENDA]]+Tabela224657[[#This Row],[MÃO DE OBRA]]-Tabela224657[[#This Row],[VALOR PAGO]] -> 0
B25: SMART | C25: 21147 | D25: 3225 | E25: 46035 | F25: LC COMPONENTES | G25: MARCELO | I25: 280.85 | J25: 46056 | K25: 46056 | L25: 280.84 | M25: =Tabela224657[[#This Row],[VENDA]]+Tabela224657[[#This Row],[MÃO DE OBRA]]-Tabela224657[[#This Row],[VALOR PAGO]] -> 0.01
B26: STK | C26: 21203 | D26: 3322 | E26: 46038 | F26: GLAUCIA | G26: SILVANO | H26: =(608.2*0.01)+17623.77 -> 17629.852 | J26: 46038 | K26: 46037 | L26: 18008.65 | M26: =Tabela224657[[#This Row],[VENDA]]+Tabela224657[[#This Row],[MÃO DE OBRA]]-Tabela224657[[#This Row],[VALOR PAGO]] -> -378.798
B27: SMART | C27: 21156 | D27: 3265 | E27: 46036 | F27: LC COMPONENTES | G27: MARCELO | I27: =(76.5+75.5+74.5+75.5+77.5+76.5+76.5)*8.91 -> 4744.575 | J27: 46057 | K27: 46058 | L27: 4744.58 | M27: =Tabela224657[[#This Row],[VENDA]]+Tabela224657[[#This Row],[MÃO DE OBRA]]-Tabela224657[[#This Row],[VALOR PAGO]] -> -0.005
B28: SMART | C28: 21177 | D28: 3240 | E28: 46037 | F28: SOARES | G28: MARCELO | I28: =(39.5+39)*3.45 -> 270.825 | J28: 46065 | K28: 46055 | L28: 270.82 | M28: =Tabela224657[[#This Row],[VENDA]]+Tabela224657[[#This Row],[MÃO DE OBRA]]-Tabela224657[[#This Row],[VALOR PAGO]] -> 0.005
B29: SMART | C29: 21181 | D29: 3239 | E29: 46038 | F29: SOARES | G29: MARCELO | I29: 718.75 | J29: 46066 | K29: 46055 | L29: 718.75 | M29: =Tabela224657[[#This Row],[VENDA]]+Tabela224657[[#This Row],[MÃO DE OBRA]]-Tabela224657[[#This Row],[VALOR PAGO]] -> 0
B30: SMART | C30: 21181 | D30: 3239 | E30: 46038 | F30: SOARES | G30: MARCELO | I30: 718.75 | J30: 46073 | K30: 46055 | L30: 718.75 | M30: =Tabela224657[[#This Row],[VENDA]]+Tabela224657[[#This Row],[MÃO DE OBRA]]-Tabela224657[[#This Row],[VALOR PAGO]] -> 0
B31: SMART | C31: 21181 | D31: 3239 | E31: 46038 | F31: SOARES | G31: MARCELO | I31: 718.75 | J31: 46080 | K31: 46055 | L31: 718.74 | M31: =Tabela224657[[#This Row],[VENDA]]+Tabela224657[[#This Row],[MÃO DE OBRA]]-Tabela224657[[#This Row],[VALOR PAGO]] -> 0.01
B32: SMART | C32: 21182 | D32: 3241 | E32: 46038 | F32: SOARES | G32: MARCELO | I32: =(198.5+319.5+315+175)*3.45/3 -> 1159.2 | J32: 46066 | K32: 46055 | L32: 1159.2 | M32: =Tabela224657[[#This Row],[VENDA]]+Tabela224657[[#This Row],[MÃO DE OBRA]]-Tabela224657[[#This Row],[VALOR PAGO]] -> 0
B33: SMART | C33: 21182 | D33: 3241 | E33: 46038 | F33: SOARES | G33: MARCELO | I33: 1159.2 | J33: 46073 | K33: 46055 | L33: 1159.2 | M33: =Tabela224657[[#This Row],[VENDA]]+Tabela224657[[#This Row],[MÃO DE OBRA]]-Tabela224657[[#This Row],[VALOR PAGO]] -> 0
B34: SMART | C34: 21182 | D34: 3241 | E34: 46038 | F34: SOARES | G34: MARCELO | I34: 1159.2 | J34: 46080 | K34: 46055 | L34: 1159.19 | M34: =Tabela224657[[#This Row],[VENDA]]+Tabela224657[[#This Row],[MÃO DE OBRA]]-Tabela224657[[#This Row],[VALOR PAGO]] -> 0.01
B35: SMART | C35: 21258 | D35: 3324 | E35: 46043 | F35: SOARES | G35: MARCELO | I35: 590.53 | J35: 46071 | K35: 46055 | L35: 590.52 | M35: =Tabela224657[[#This Row],[VENDA]]+Tabela224657[[#This Row],[MÃO DE OBRA]]-Tabela224657[[#This Row],[VALOR PAGO]] -> 0.01
B36: STK | C36: 21206 | D36: 3325 | E36: 46038 | F36: NOSSA SRA DE FAT | G36: MARCIANO | H36: 1346.76 | J36: 46038 | K36: 46038 | L36: 1346.76 | M36: =Tabela224657[[#This Row],[VENDA]]+Tabela224657[[#This Row],[MÃO DE OBRA]]-Tabela224657[[#This Row],[VALOR PAGO]] -> 0
B37: SMART | C37: 21263 | D37: 3347 | E37: 46043 | F37: LC COMPONENTES | G37: MARCELO | I37: 949.19 | J37: 46078 | K37: 46078 | L37: 949.19 | M37: =Tabela224657[[#This Row],[VENDA]]+Tabela224657[[#This Row],[MÃO DE OBRA]]-Tabela224657[[#This Row],[VALOR PAGO]] -> 0
B38: STK | C38: 21280 | D38: 3363 | E38: 46044 | F38: GLAUCIA | G38: SILVANO | H38: 3530.14 | K38: 46042 | L38: 3628.56 | M38: =Tabela224657[[#This Row],[VENDA]]+Tabela224657[[#This Row],[MÃO DE OBRA]]-Tabela224657[[#This Row],[VALOR PAGO]] -> -98.42
B39: SMART | C39: 21277 | D39: 3361 | E39: 46044 | F39: SOARES | G39: MARCELO | I39: 116.8 | J39: 46072 | K39: 46055 | L39: 116.8 | M39: =Tabela224657[[#This Row],[VENDA]]+Tabela224657[[#This Row],[MÃO DE OBRA]]-Tabela224657[[#This Row],[VALOR PAGO]] -> 0
B40: SMART | C40: 21395 | D40: 3390 | E40: 46052 | F40: SOARES | G40: MARCELO | I40: 91.43 | J40: 46080 | K40: 46071 | L40: 91.42 | M40: =Tabela224657[[#This Row],[VENDA]]+Tabela224657[[#This Row],[MÃO DE OBRA]]-Tabela224657[[#This Row],[VALOR PAGO]] -> 0.01
B41: SMART | C41: 21395 | D41: 3390 | E41: 46052 | F41: SOARES | G41: MARCELO | I41: 91.43 | J41: 46087 | K41: 46071 | L41: 91.42 | M41: =Tabela224657[[#This Row],[VENDA]]+Tabela224657[[#This Row],[MÃO DE OBRA]]-Tabela224657[[#This Row],[VALOR PAGO]] -> 0.01
B42: SMART | C42: 21395 | D42: 3390 | E42: 46052 | F42: SOARES | G42: MARCELO | I42: 91.42 | J42: 46094 | K42: 46072 | L42: 91.43 | M42: =Tabela224657[[#This Row],[VENDA]]+Tabela224657[[#This Row],[MÃO DE OBRA]]-Tabela224657[[#This Row],[VALOR PAGO]] -> -0.01
...

Sheet Fevereiro 2026
B2: FRETES
B4: MÊS | C4: SMART | H4: STK
C5: 2023 | D5: 2024 | E5: 2025 | F5: 2026 | G5: 2027 | H5: 2025 | I5: 2026 | J5: 2027 | K5: 2028 | L5: 2029 | M5: 2030
B6: JANEIRO | C6: 126073.37 | D6: 270562.53 | E6: 49887.66 | F6: 0 | G6: 0 | H6: 0 | I6: 0 | J6: 0 | K6: 0 | L6: 0 | M6: 0
B7: FEVEREIRO | C7: 166235.96 | D7: 324984.97 | E7: 15513.83 | F7: 0 | G7: 0 | H7: 0 | I7: 0 | J7: 0 | K7: 0 | L7: 0 | M7: 0
B8: MARÇO | C8: 119814.85 | D8: 256001.57 | E8: 32410.22 | F8: 0 | G8: 0 | H8: 0 | I8: 0 | J8: 0 | K8: 0 | L8: 0 | M8: 0
B9: ABRIL | C9: 112668.22 | D9: 136419.94 | E9: 23117.53 | F9: 0 | G9: 0 | H9: 0 | I9: 0 | J9: 0 | K9: 0 | L9: 0 | M9: 0
B10: MAIO | C10: 39597.94 | D10: 57014.4 | E10: 11710.4 | F10: 0 | G10: 0 | H10: 0 | I10: 0 | J10: 0 | K10: 0 | L10: 0 | M10: 0
B11: JUNHO | C11: 77419.24 | D11: 259261.92 | E11: 32986.86 | F11: 0 | G11: 0 | H11: 0 | I11: 0 | J11: 0 | K11: 0 | L11: 0 | M11: 0
B12: JULHO | C12: 74963.62 | D12: 191964.91 | E12: 8086.81 | F12: 0 | G12: 0 | H12: 0 | I12: 0 | J12: 0 | K12: 0 | L12: 0 | M12: 0
B13: AGOSTO | C13: 152485.66 | D13: 273158.85 | E13: 22122.22 | F13: 0 | G13: 0 | H13: 0 | I13: 0 | J13: 0 | K13: 0 | L13: 0 | M13: 0
B14: SETEMBRO | C14: 171282.48 | D14: 63159.51 | E14: 36466.42 | F14: 0 | G14: 0 | H14: 0 | I14: 0 | J14: 0 | K14: 0 | L14: 0 | M14: 0
B15: OUTUBRO | C15: 168433.06 | D15: 53077.38 | E15: 99828 | F15: 0 | G15: 0 | I15: 0 | J15: 0 | K15: 0 | L15: 0 | M15: 0
B16: NOVEMBRO | C16: 155757.68 | D16: 15517.44 | E16: 0 | F16: 0 | G16: 0 | H16: 0 | I16: 0 | J16: 0 | K16: 0 | L16: 0 | M16: 0
B17: DEZEMBRO | C17: 163379.08 | D17: 9580.01 | E17: 0 | F17: 0 | G17: 0 | H17: 0 | I17: 0 | J17: 0 | K17: 0 | L17: 0 | M17: 0
B18: TOTAL | C18: =SUM(C6:C17) -> 1528111.2 | D18: =SUM(D6:D17) -> 1910703.4 | E18: =SUM(E6:E17) -> 332129.95 | F18: =SUM(F6:F17) -> 0 | G18: 0 | H18: =SUM(H6:H17) -> 0 | I18: 0 | J18: =SUM(J6:J17) -> 0 | K18: 0 | L18: =SUM(L6:L17) -> 0 | M18: 0
B19: TOTAL CONSOLIDADO 2026: | D19: =SUM(I18+F18) -> 0
B20: EMPRESA | C20: NOTA FISCAL | D20: PEDIDO | E20: DATA DE EMISSÃO | F20: DESTINATÁRIO | G20: REPRESENTANTE | H20: VENDA | I20: MÃO DE OBRA | J20: VENCIMENTO | K20: DATA DE PAGAMENTO | L20: VALOR PAGO | M20: VALOR EM ABERTO | N20: Coluna1
B21: STK | C21: 21626 | D21: 3369 | E21: 46066 | F21: GLAUCIA | G21: SILVANO | H21: 2875.2 | J21: 46066 | K21: 46066 | L21: 2875.2 | M21: =Tabela2246578[[#This Row],[VENDA]]+Tabela2246578[[#This Row],[MÃO DE OBRA]]-Tabela2246578[[#This Row],[VALOR PAGO]] -> 0
B22: SMART | C22: 21440 | D22: 3389 | E22: 46056 | F22: SOARES | G22: MARCELO | I22: 119.35 | J22: 46084 | K22: 46071 | L22: 119.35 | M22: =Tabela2246578[[#This Row],[VENDA]]+Tabela2246578[[#This Row],[MÃO DE OBRA]]-Tabela2246578[[#This Row],[VALOR PAGO]] -> 0
B23: SMART | C23: 21440 | D23: 3389 | E23: 46056 | F23: SOARES | G23: MARCELO | I23: 119.35 | J23: 46091 | K23: 46071 | L23: 119.35 | M23: =Tabela2246578[[#This Row],[VENDA]]+Tabela2246578[[#This Row],[MÃO DE OBRA]]-Tabela2246578[[#This Row],[VALOR PAGO]] -> 0
B24: SMART | C24: 21440 | D24: 3389 | E24: 46056 | F24: SOARES | G24: MARCELO | I24: 119.35 | J24: 46098 | K24: 46076 | L24: 119.35 | M24: =Tabela2246578[[#This Row],[VENDA]]+Tabela2246578[[#This Row],[MÃO DE OBRA]]-Tabela2246578[[#This Row],[VALOR PAGO]] -> 0
